Traceback (most recent call last):
  File "hi.py", line 1, in <module>
    from mpi4py import MPI
ImportError: libmpi.so.12: cannot open shared object file: No such file or directory
Traceback (most recent call last):
  File "hi.py", line 1, in <module>
    from mpi4py import MPI
ImportError: libmpi.so.12: cannot open shared object file: No such file or directory
Traceback (most recent call last):
  File "hi.py", line 1, in <module>
    from mpi4py import MPI
ImportError: libmpi.so.12: cannot open shared object file: No such file or directory
Traceback (most recent call last):
  File "hi.py", line 1, in <module>
    from mpi4py import MPI
ImportError: libmpi.so.12: cannot open shared object file: No such file or directory
--------------------------------------------------------------------------
Primary job  terminated normally, but 1 process returned
a non-zero exit code. Per user-direction, the job has been aborted.
--------------------------------------------------------------------------
--------------------------------------------------------------------------
mpiexec detected that one or more processes exited with non-zero status, thus causing
the job to be terminated. The first process to do so was:

  Process name: [[64098,1],3]
  Exit code:    1
--------------------------------------------------------------------------
